<?xml version="1.0"?>
<robot name="6-revolute_biped">

  <material name="blue"><color rgba="0.0 0.0 0.8 1.0"/></material>
  <material name="grey"><color rgba="0.5 0.5 0.5 1.0"/></material>
  <material name="dark_grey"><color rgba="0.3 0.3 0.3 1.0"/></material>

  <link name="torso">
    <visual>
      <origin xyz="0 0 0.25" rpy="0 0 0"/>
      <geometry><box size="0.2 0.15 0.5"/></geometry>
      <material name="blue"/>
    </visual>
    <collision>
      <origin xyz="0 0 0.25" rpy="0 0 0"/>
      <geometry><box size="0.2 0.15 0.5"/></geometry>
    </collision>
    <inertial>
      <mass value="5.0"/>
      <inertia ixx="0.130" ixy="0.0" ixz="0.0" iyy="0.121" iyz="0.0" izz="0.043"/>
    </inertial>
  </link>

  <joint name="left_hip" type="revolute">
    <parent link="torso"/>
    <child link="left_thigh"/>
    <origin xyz="0 0.075 0" rpy="0 0 0"/>
    <axis xyz="0 1 0"/>
    <limit effort="150" velocity="6.0" lower="-0.8" upper="0.8"/>
    <dynamics damping="3.0" friction="0.5"/>
  </joint>

  <link name="left_thigh">
    <visual>
      <origin xyz="0 0 -0.2" rpy="0 0 0"/>
      <geometry><cylinder length="0.4" radius="0.04"/></geometry>
      <material name="grey"/>
    </visual>
    <collision>
      <origin xyz="0 0 -0.2" rpy="0 0 0"/>
      <geometry><cylinder length="0.4" radius="0.04"/></geometry>
    </collision>
    <inertial>
      <mass value="1.0"/>
      <inertia ixx="0.014" ixy="0.0" ixz="0.0" iyy="0.014" iyz="0.0" izz="0.001"/>
    </inertial>
  </link>

  <joint name="left_knee" type="revolute">
    <parent link="left_thigh"/>
    <child link="left_shin"/>
    <origin xyz="0 0 -0.4" rpy="0 0 0"/>
    <axis xyz="0 1 0"/>
    <limit effort="100" velocity="6.0" lower="0.0" upper="2.5"/>
    <dynamics damping="3.0" friction="0.5"/>
  </joint>

  <link name="left_shin">
    <visual>
      <origin xyz="0 0 -0.15" rpy="0 0 0"/>
      <geometry><cylinder length="0.3" radius="0.03"/></geometry>
      <material name="grey"/>
    </visual>
    <collision>
      <origin xyz="0 0 -0.15" rpy="0 0 0"/>
      <geometry><cylinder length="0.3" radius="0.03"/></geometry>
    </collision>
    <inertial>
      <mass value="1.0"/>
      <inertia ixx="0.0079" ixy="0.0" ixz="0.0" iyy="0.0079" iyz="0.0" izz="0.0008"/>
    </inertial>
  </link>

  <joint name="left_ankle" type="revolute">
    <parent link="left_shin"/>
    <child link="left_foot"/>
    <origin xyz="0 0 -0.3" rpy="0 0 0"/>
    <axis xyz="0 1 0"/>
    <limit effort="40" velocity="4.0" lower="-0.4" upper="0.4"/>
    <dynamics damping="1.5" friction="0.2"/>
  </joint>

  <link name="left_foot">
    <visual>
      <origin xyz="0.05 0 -0.015" rpy="0 0 0"/>
      <geometry><box size="0.15 0.08 0.03"/></geometry>
      <material name="dark_grey"/>
    </visual>
    <collision>
      <origin xyz="0.05 0 -0.015" rpy="0 0 0"/>
      <geometry><box size="0.15 0.08 0.03"/></geometry>
    </collision>
    <inertial>
      <mass value="0.5"/>
      <inertia ixx="0.0001" ixy="0.0" ixz="0.0" iyy="0.0009" iyz="0.0" izz="0.0009"/>
    </inertial>
  </link>

  <joint name="right_hip" type="revolute">
    <parent link="torso"/>
    <child link="right_thigh"/>
    <origin xyz="0 -0.075 0" rpy="0 0 0"/>
    <axis xyz="0 1 0"/>
    <limit effort="150" velocity="6.0" lower="-0.8" upper="0.8"/>
    <dynamics damping="3.0" friction="0.5"/>
  </joint>

  <link name="right_thigh">
    <visual>
      <origin xyz="0 0 -0.2" rpy="0 0 0"/>
      <geometry><cylinder length="0.4" radius="0.04"/></geometry>
      <material name="grey"/>
    </visual>
    <collision>
      <origin xyz="0 0 -0.2" rpy="0 0 0"/>
      <geometry><cylinder length="0.4" radius="0.04"/></geometry>
    </collision>
    <inertial>
      <mass value="1.0"/>
      <inertia ixx="0.014" ixy="0.0" ixz="0.0" iyy="0.014" iyz="0.0" izz="0.001"/>
    </inertial>
  </link>

  <joint name="right_knee" type="revolute">
    <parent link="right_thigh"/>
    <child link="right_shin"/>
    <origin xyz="0 0 -0.4" rpy="0 0 0"/>
    <axis xyz="0 1 0"/>
    <limit effort="100" velocity="6.0" lower="0.0" upper="2.5"/>
    <dynamics damping="3.0" friction="0.5"/>
  </joint>

  <link name="right_shin">
    <visual>
      <origin xyz="0 0 -0.15" rpy="0 0 0"/>
      <geometry><cylinder length="0.3" radius="0.03"/></geometry>
      <material name="grey"/>
    </visual>
    <collision>
      <origin xyz="0 0 -0.15" rpy="0 0 0"/>
      <geometry><cylinder length="0.3" radius="0.03"/></geometry>
    </collision>
    <inertial>
      <mass value="1.0"/>
      <inertia ixx="0.0079" ixy="0.0" ixz="0.0" iyy="0.0079" iyz="0.0" izz="0.0008"/>
    </inertial>
  </link>

  <joint name="right_ankle" type="revolute">
    <parent link="right_shin"/>
    <child link="right_foot"/>
    <origin xyz="0 0 -0.3" rpy="0 0 0"/>
    <axis xyz="0 1 0"/>
    <limit effort="40" velocity="4.0" lower="-0.4" upper="0.4"/>
    <dynamics damping="1.5" friction="0.2"/>
  </joint>

  <link name="right_foot">
    <visual>
      <origin xyz="0.05 0 -0.015" rpy="0 0 0"/>
      <geometry><box size="0.15 0.08 0.03"/></geometry>
      <material name="dark_grey"/>
    </visual>
    <collision>
      <origin xyz="0.05 0 -0.015" rpy="0 0 0"/>
      <geometry><box size="0.15 0.08 0.03"/></geometry>
    </collision>
    <inertial>
      <mass value="0.5"/>
      <inertia ixx="0.0001" ixy="0.0" ixz="0.0" iyy="0.0009" iyz="0.0" izz="0.0009"/>
    </inertial>
  </link>

</robot>